Workbook

Sheet Sheet5
A1: Category | B1: Column
A3: Row Labels | B3: Count of Column_ID
A4: 2 | B4: 68
A5: 4 | B5: 53
A6: 5 | B6: 24
A7: 6 | B7: 152
A8: Grand Total | B8: 297

Sheet column_progress
A1: Full_ID | B1: Tower | C1: Level | D1: Zone | E1: SOW | F1: Column_ID | G1: fwk_pc13 | H1: rebar_pc13 | I1: concrete_pc13 | J1: Category | K1: fwk_pc14 | L1: rebar_pc14 | M1: concrete_pc14
A2: T3-L4-Z17_MC-C1 | B2: T3 | C2: L4 | D2: Z17_MC | E2: 4 | F2: C1 | G2: 0 | H2: 0 | I2: 0 | J2: MC | K2: 1 | L2: 1 | M2: 1
A3: T3-L4-Z17_MC-C2 | B3: T3 | C3: L4 | D3: Z17_MC | E3: 4 | F3: C2 | G3: 0 | H3: 0 | I3: 0 | J3: MC | K3: 1 | L3: 1 | M3: 1
A4: T3-L4-Z17_MC-C3 | B4: T3 | C4: L4 | D4: Z17_MC | E4: 4 | F4: C3 | G4: 0 | H4: 0 | I4: 0 | J4: MC | K4: 1 | L4: 1 | M4: 1
A5: T3-L4-Z17_MC-C4 | B5: T3 | C5: L4 | D5: Z17_MC | E5: 4 | F5: C4 | G5: 0 | H5: 0 | I5: 0 | J5: MC | K5: 1 | L5: 1 | M5: 1
A6: T3-L4-Z17_MC-C5 | B6: T3 | C6: L4 | D6: Z17_MC | E6: 4 | F6: C5 | G6: 0 | H6: 0 | I6: 0 | J6: MC | K6: 1 | L6: 1 | M6: 1
A7: T3-L4-Z17_MC-C6 | B7: T3 | C7: L4 | D7: Z17_MC | E7: 4 | F7: C6 | G7: 0 | H7: 0 | I7: 0 | J7: MC | K7: 1 | L7: 1 | M7: 1
A8: T3-L4-Z17_MC-C7 | B8: T3 | C8: L4 | D8: Z17_MC | E8: 4 | F8: C7 | G8: 0 | H8: 0 | I8: 0 | J8: MC | K8: 1 | L8: 1 | M8: 1
A9: T3-L4-Z17_MC-C8 | B9: T3 | C9: L4 | D9: Z17_MC | E9: 4 | F9: C8 | G9: 0 | H9: 0 | I9: 0 | J9: MC | K9: 1 | L9: 1 | M9: 1
A10: T3-L4-Z17_MC-C9 | B10: T3 | C10: L4 | D10: Z17_MC | E10: 4 | F10: C9 | G10: 0 | H10: 0 | I10: 0 | J10: MC | K10: 1 | L10: 1 | M10: 1
A11: T3-L4-Z17_MC-C10 | B11: T3 | C11: L4 | D11: Z17_MC | E11: 4 | F11: C10 | G11: 0 | H11: 0 | I11: 0 | J11: MC | K11: 1 | L11: 1 | M11: 1
A12: T3-L4-Z17_MC-C11 | B12: T3 | C12: L4 | D12: Z17_MC | E12: 4 | F12: C11 | G12: 0 | H12: 0 | I12: 0 | J12: MC | K12: 1 | L12: 1 | M12: 1
A13: T3-L4-Z17_MC-C12 | B13: T3 | C13: L4 | D13: Z17_MC | E13: 4 | F13: C12 | G13: 0 | H13: 0 | I13: 0 | J13: MC | K13: 1 | L13: 1 | M13: 1
... A42: T3-L3-Z11-C23 | B42: T3 | C42: L3 | D42: Z11 | E42: 4 | F42: C23 | G42: 1 | H42: 1 | I42: 1 | J42: Column | K42: 1 | L42: 1 | M42: 1
A43: T3-L3-Z12-C1 | B43: T3 | C43: L3 | D43: Z12 | E43: 4 | F43: C1 | G43: 1 | H43: 1 | J43: Column | K43: 1 | L43: 1 | M43: 1
A44: T3-L3-Z12-C2 | B44: T3 | C44: L3 | D44: Z12 | E44: 4 | F44: C2 | J44: Column | K44: 1 | L44: 1 | M44: 1
A45: T3-L3-Z12-C3 | B45: T3 | C45: L3 | D45: Z12 | E45: 4 | F45: C3 | J45: Column | K45: 1 | L45: 1 | M45: 1
A46: T3-L3-Z12-C4 | B46: T3 | C46: L3 | D46: Z12 | E46: 4 | F46: C4 | J46: Column | K46: 1 | L46: 1 | M46: 1
A47: T3-L3-Z12-C5 | B47: T3 | C47: L3 | D47: Z12 | E47: 4 | F47: C5 | G47: 1 | H47: 1 | J47: Column | K47: 1 | L47: 1 | M47: 1
A48: T3-L3-Z12-C6 | B48: T3 | C48: L3 | D48: Z12 | E48: 4 | F48: C6 | J48: Column | K48: 1 | L48: 1 | M48: 1
A49: T3-L3-Z12-C7 | B49: T3 | C49: L3 | D49: Z12 | E49: 4 | F49: C7 | J49: Column | K49: 1 | L49: 1 | M49: 1
A50: T3-L3-Z12-C8 | B50: T3 | C50: L3 | D50: Z12 | E50: 4 | F50: C8 | G50: 1 | H50: 1 | J50: Column | K50: 1 | L50: 1 | M50: 1
A51: T3-L3-Z12-C9 | B51: T3 | C51: L3 | D51: Z12 | E51: 4 | F51: C9 | G51: 1 | H51: 1 | J51: Column | K51: 1 | L51: 1 | M51: 1
A52: T3-L3-Z12-C10 | B52: T3 | C52: L3 | D52: Z12 | E52: 4 | F52: C10 | J52: Column | K52: 1 | L52: 1 | M52: 1
A53: T3-L3-Z12-C11 | B53: T3 | C53: L3 | D53: Z12 | E53: 4 | F53: C11 | J53: Column | K53: 1 | L53: 1 | M53: 1
A54: T3-L3-Z12-C12 | B54: T3 | C54: L3 | D54: Z12 | E54: 4 | F54: C12 | G54: 1 | H54: 1 | J54: Column | K54: 1 | L54: 1 | M54: 1
A55: T3-L3-Z14-C1 | B55: T3 | C55: L3 | D55: Z14 | E55: 4 | F55: C1 | J55: Column | L55: 1
A56: T3-L3-Z14-C2 | B56: T3 | C56: L3 | D56: Z14 | E56: 4 | F56: C2 | J56: Column | L56: 1
A57: T3-L3-Z14-C3 | B57: T3 | C57: L3 | D57: Z14 | E57: 4 | F57: C3 | J57: Column | L57: 1
A58: T3-L3-Z14-C4 | B58: T3 | C58: L3 | D58: Z14 | E58: 4 | F58: C4 | J58: Column | L58: 1
A59: T3-L3-Z14-C5 | B59: T3 | C59: L3 | D59: Z14 | E59: 4 | F59: C5 | J59: Column | L59: 1
A60: T3-L3-Z14-C6 | B60: T3 | C60: L3 | D60: Z14 | E60: 4 | F60: C6 | J60: Column | L60: 1
A61: T3-L3-Z14-C7 | B61: T3 | C61: L3 | D61: Z14 | E61: 4 | F61: C7 | J61: Column | L61: 1
A62: T3-L3-Z14-C8 | B62: T3 | C62: L3 | D62: Z14 | E62: 4 | F62: C8 | J62: Column | L62: 1
A63: T3-L3-Z14-C9 | B63: T3 | C63: L3 | D63: Z14 | E63: 4 | F63: C9 | J63: Column | L63: 1
A64: T3-L3-Z14-C10 | B64: T3 | C64: L3 | D64: Z14 | E64: 4 | F64: C10 | J64: Column | L64: 1
A65: T3-L3-Z14-C11 | B65: T3 | C65: L3 | D65: Z14 | E65: 4 | F65: C11 | J65: Column | L65: 1
A66: T3-L3-Z14-C12 | B66: T3 | C66: L3 | D66: Z14 | E66: 4 | F66: C12 | J66: Column | L66: 1
A67: T3-L4-Z15_MC-C1 | B67: T3 | C67: L4 | D67: Z15_MC | E67: 4 | F67: C1 | G67: 1 | H67: 1 | I67: 1 | J67: MC | K67: 1 | L67: 1 | M67: 1
A68: T3-L4-Z15_MC-C2 | B68: T3 | C68: L4 | D68: Z15_MC | E68: 4 | F68: C2 | G68: 1 | H68: 1 | I68: 1 | J68: MC | K68: 1 | L68: 1 | M68: 1
...

Sheet pivot
A1: Tower | B1: T3
A2: Category | B2: Column
A4: Row Labels | B4: Sum of fwk_pc13 | C4: Sum of rebar_pc13 | D4: Sum of concrete_pc13 | E4: Sum of fwk_pc14 | F4: Sum of rebar_pc14 | G4: Sum of concrete_pc14
A5: L3 | B5: 34 | C5: 34 | D5: 29 | E5: 41 | F5: 53 | G5: 41
A6: 4 | B6: 34 | C6: 34 | D6: 29 | E6: 41 | F6: 53 | G6: 41
A7: Grand Total | B7: 34 | C7: 34 | D7: 29 | E7: 41 | F7: 53 | G7: 41

Sheet Column_Summary
A1: Tower | B1: Level | C1: SOW | D1: Column_nos | E1: Progress_PC13 | F1: Progress_PC14 | G1: %_progress_PC13 | H1: %_progress_PC14
A2: T4 | B2: L1 | C2: 2 | D2: =COUNTIFS(column_progress!B:B,$A2, column_progress!C:C,$B2, column_progress!E:E,TRIM($C2)) -> 68 | E2: =AVERAGE(pivot!B6:D6) -> 32.333333 | F2: =AVERAGE(pivot!E6:G6) -> 45 | G2: =E2/D2 -> 0.4754902 | H2: =F2/D2 -> 0.66176471
A3: T4 | B3: L1 | C3: 5 | D3: =COUNTIFS(column_progress!B:B,$A3, column_progress!C:C,$B3, column_progress!E:E,TRIM($C3)) -> 24 | E3: 24 | F3: 24 | G3: =E3/D3 -> 1 | H3: =F3/D3 -> 1
A4: T4 | B4: L1M | C4: 6 | D4: =COUNTIFS(column_progress!B:B,$A4, column_progress!C:C,$B4, column_progress!E:E,TRIM($C4)) -> 35 | E4: 35 | F4: 35 | G4: =E4/D4 -> 1 | H4: =F4/D4 -> 1
A5: T4 | B5: L2 | C5: 6 | D5: =COUNTIFS(column_progress!B:B,$A5, column_progress!C:C,$B5, column_progress!E:E,TRIM($C5)) -> 117 | E5: =AVERAGE(pivot!B6:D6) -> 32.333333 | F5: =AVERAGE(pivot!E6:G6) -> 45 | G5: =E5/D5 -> 0.27635328 | H5: =F5/D5 -> 0.38461538
A6: T3 | B6: L1 | C6: 2 | D6: 14 | E6: 14 | F6: 14 | G6: =E6/D6 -> 1 | H6: =F6/D6 -> 1
A7: T3 | B7: L1 | C7: 4 | D7: 10 | E7: 10 | F7: 10 | G7: =E7/D7 -> 1 | H7: =F7/D7 -> 1
A8: T3 | B8: L3 | C8: 4 | D8: =COUNTIFS(column_progress!B:B,$A8, column_progress!C:C,$B8, column_progress!E:E,TRIM($C8)) -> 53 | E8: =AVERAGE(pivot!B6:D6) -> 32.333333 | F8: =AVERAGE(pivot!E6:G6) -> 45 | G8: =E8/D8 -> 0.61006289 | H8: =F8/D8 -> 0.8490566
D10: =D6+D2 -> 82 | E10: =E2+E6 -> 46.333333 | F10: =F2+F6 -> 59 | G10: =G2+G6 -> 1.4754902 | H10: =H2+H6 -> 1.6617647
D11: =D7+D8 -> 63 | E11: =E7+E8 -> 42.333333 | F11: =F7+F8 -> 55
D12: =D4+D5 -> 152 | E12: =E4+E5 -> 67.333333 | F12: =F4+F5 -> 80

Sheet Pivot_SOW
A3: Row Labels | B3: Sum of Column_nos | C3: Sum of Progress_PC13 | D3: Sum of Progress_PC14 | E3: %_progress_PC13 | F3: %_progress_PC14
A4: 2 | B4: 82 | C4: 67.666667 | D4: 75.666667 | E4: =C4/B4*100 -> 82.520325 | F4: =D4/B4*100 -> 92.276423
A5: 4 | B5: 63 | C5: 63.666667 | D5: 71.666667 | E5: =C5/B5*100 -> 101.0582 | F5: =D5/B5*100 -> 113.75661
A6: 5 | B6: 24 | C6: 24 | D6: 24 | E6: =C6/B6*100 -> 100 | F6: =D6/B6*100 -> 100
A7: 6 | B7: 152 | C7: 98 | D7: 100.66667 | E7: =C7/B7*100 -> 64.473684 | F7: =D7/B7*100 -> 66.22807
A8: Grand Total | B8: 321 | C8: 253.33333 | D8: 272

Sheet Sheet6
A1: SOW | B1: Column_nos | C1: Progress_PC13 | D1: Progress_PC14 | E1: %_progress_PC13 | F1: %_progress_PC14
A2: 2 | B2: 82 | C2: 46.33 | D2: 59 | E2: =C2/B2*100 -> 56.5 | F2: =D2/B2*100 -> 71.95122
A3: 4 | B3: 63 | C3: 42.33 | D3: 55 | E3: =C3/B3*100 -> 67.190476 | F3: =D3/B3*100 -> 87.301587
A4: 5 | B4: 24 | C4: 24 | D4: 24 | E4: =C4/B4*100 -> 100 | F4: =D4/B4*100 -> 100
A5: 6 | B5: 152 | C5: 67.33 | D5: 80 | E5: =C5/B5*100 -> 44.296053 | F5: =D5/B5*100 -> 52.631579
