Workbook

Sheet monthly_progress
A1: Tower | B1: Level | C1: zone | D1: SOW | E1: area_m2 | F1: fwk_pc13 | G1: fwk_pc14 | H1: rebar_pc13 | I1: rebar_pc14 | J1: concrete_pc13 | K1: concrete_pc14 | L1: pt_pc13 | M1: pt_pc14 | N1: category
A2: T4 | B2: LG2 | C2: Zone 1 | D2: 2 | E2: 109 | F2: 1 | G2: 1 | H2: 1 | I2: 1 | J2: 1 | K2: 1 | L2: non-pt | M2: non-pt | N2: non-pt
A3: T4 | B3: LG1 | C3: Zone 2 | D3: 2 | E3: 150 | F3: 1 | G3: 1 | H3: 1 | I3: 1 | J3: 1 | K3: 1 | L3: non-pt | M3: non-pt | N3: non-pt
A4: T4 | B4: LG1 | C4: Zone 3 | D4: 2 | E4: 193 | F4: 1 | G4: 1 | H4: 1 | I4: 1 | J4: 1 | K4: 1 | L4: non-pt | M4: non-pt | N4: non-pt
A5: T4 | B5: GF | C5: Zone 4 | D5: 2 | E5: 936 | F5: 1 | G5: 1 | H5: 1 | I5: 1 | J5: 1 | K5: 1 | L5: non-pt | M5: non-pt | N5: non-pt
A6: T4 | B6: GF | C6: Zone 5.1 | D6: 2 | E6: 171 | F6: 0 | G6: 0 | H6: 0 | I6: 0 | J6: 0 | K6: 0 | L6: non-pt | M6: non-pt | N6: non-pt
A7: T4 | B7: GF | C7: Zone 5.2 | D7: 2 | E7: 35 | F7: 0 | G7: 0 | H7: 0 | I7: 0 | J7: 0 | K7: 0 | L7: non-pt | M7: non-pt | N7: non-pt
A8: T4 | B8: GF | C8: Zone 5.3 | D8: 2 | E8: 147 | F8: 0 | G8: 0 | H8: 0 | I8: 0 | J8: 0 | K8: 0 | L8: non-pt | M8: non-pt | N8: non-pt
A9: T4 | B9: GF | C9: Zone 5.4 | D9: 2 | E9: 42 | F9: 0 | G9: 0 | H9: 0 | I9: 0 | J9: 0 | K9: 0 | L9: non-pt | M9: non-pt | N9: non-pt
A10: T4 | B10: GF | C10: Zone 5.5 | D10: 2 | E10: 34 | F10: 0 | G10: 0 | H10: 0 | I10: 0 | J10: 0 | K10: 0 | L10: non-pt | M10: non-pt | N10: non-pt
A11: T4 | B11: GF | C11: Zone 5.6 | D11: 2 | E11: 19 | F11: 1 | G11: 1 | H11: 1 | I11: 1 | J11: 1 | K11: 1 | L11: non-pt | M11: non-pt | N11: non-pt
A12: T4 | B12: L1 | C12: Zone 6 | D12: 2 | E12: 723 | F12: 1 | G12: 1 | H12: 1 | I12: 1 | J12: 1 | K12: 1 | L12: non-pt | M12: non-pt | N12: non-pt
A13: T4 | B13: L1 | C13: Zone 7 | D13: 2 | E13: 922 | F13: 1 | G13: 1 | H13: 1 | I13: 1 | J13: 1 | K13: 1 | L13: non-pt | M13: non-pt | N13: non-pt
... A23: T4 | B23: L1M | C23: Zone 15 | D23: 2 | E23: 578 | F23: 1 | G23: 1 | H23: 1 | I23: 1 | J23: 1 | K23: 1 | L23: non-pt | M23: non-pt | N23: non-pt
A24: T4 | B24: L1M | C24: Zone 16 | D24: 6 | E24: 901 | F24: 1 | G24: 1 | H24: 1 | I24: 1 | J24: 1 | K24: 1 | L24: 1 | M24: 1 | N24: pt
A25: T4 | B25: L1M | C25: Zone 17 | D25: 6 | E25: 366 | F25: 1 | G25: 1 | H25: 1 | I25: 1 | J25: 1 | K25: 1 | L25: 1 | M25: 1 | N25: pt
A26: T4 | B26: L1M | C26: Zone 18 | D26: 6 | E26: 370 | F26: 1 | G26: 1 | H26: 1 | I26: 1 | J26: 1 | K26: 1 | L26: 1 | M26: 1 | N26: pt
A27: T4 | B27: L1M | C27: Zone 19 | D27: 6 | E27: 430 | F27: 0.7 | G27: 0.7 | H27: 0.7 | I27: 0.7 | J27: 0.7 | K27: 0.7 | L27: non-pt | M27: non-pt | N27: non-pt
A28: T4 | B28: L1M | C28: Zone 20 | D28: 6 | E28: 565 | F28: 1 | G28: 1 | H28: 1 | I28: 1 | J28: 1 | K28: 1 | L28: non-pt | M28: non-pt | N28: non-pt
A29: T4 | B29: L1M | C29: Zone 21.1 | D29: 2 | E29: 45 | F29: 1 | G29: 1 | H29: 1 | I29: 1 | J29: 0 | K29: 0 | L29: non-pt | M29: non-pt | N29: non-pt
A30: T4 | B30: L1M | C30: Zone 21.2 | D30: 2 | E30: 73 | F30: 0 | G30: 0 | H30: 0 | I30: 0 | J30: 0 | K30: 0 | L30: non-pt | M30: non-pt | N30: non-pt
A31: T4 | B31: L1M | C31: Zone 21.3 | D31: 6 | E31: 26 | F31: 0 | G31: 0 | H31: 0 | I31: 0 | J31: 0 | K31: 0 | L31: non-pt | M31: non-pt | N31: non-pt
A32: T4 | B32: L1M | C32: Zone 21.4 | D32: 2 | E32: 40 | F32: 0 | G32: 0 | H32: 0 | I32: 0 | J32: 0 | K32: 0 | L32: non-pt | M32: non-pt | N32: non-pt
A33: T4 | B33: L1M | C33: Zone 21.5 | D33: 2 | E33: 95 | F33: 1 | G33: 1 | H33: 1 | I33: 1 | J33: 1 | K33: 1 | L33: non-pt | M33: non-pt | N33: non-pt
A34: T4 | B34: L1M | C34: Zone 21.6 | D34: 2 | E34: 48 | F34: 1 | G34: 1 | H34: 1 | I34: 1 | J34: 0 | K34: 0 | L34: non-pt | M34: non-pt | N34: non-pt
A35: T4 | B35: L1M | C35: Zone 21.7 | D35: 2 | E35: 114 | F35: 0 | G35: 0 | H35: 0 | I35: 0 | J35: 0 | K35: 0 | L35: non-pt | M35: non-pt | N35: non-pt
A36: T4 | B36: L2 | C36: Zone 22 | D36: 6 | E36: 1605 | F36: 1 | G36: 1 | H36: 1 | I36: 1 | J36: 1 | K36: 1 | L36: 0.9 | M36: 0.9 | N36: pt
A37: T4 | B37: L2 | C37: Zone 23 | D37: 6 | E37: 1265 | F37: 1 | G37: 1 | H37: 1 | I37: 1 | J37: 1 | K37: 1 | L37: 0.9 | M37: 0.9 | N37: pt
A38: T4 | B38: L2 | C38: Zone 24 | D38: 6 | E38: 1687 | F38: 1 | G38: 1 | H38: 1 | I38: 1 | J38: 1 | K38: 1 | L38: 0.9 | M38: 0.9 | N38: pt
A39: T4 | B39: L2 | C39: Zone 25 | D39: 6 | E39: 1372 | F39: 0.4 | G39: 0.4 | H39: 0.4 | I39: 0.4 | J39: 0 | K39: 0 | L39: 0 | M39: 0 | N39: pt
A40: T4 | B40: L2 | C40: Zone 26 | D40: 6 | E40: 1773 | F40: 0.09 | G40: 1 | H40: 0.09 | I40: 0.09 | J40: 0.09 | K40: 0.09 | L40: 0.09 | M40: 0.09 | N40: pt
A41: T4 | B41: L2 | C41: Zone 27 | D41: 6 | E41: 803 | F41: 0.35 | G41: 0.35 | H41: 0.35 | I41: 0.35 | J41: 0.35 | K41: 0.35 | L41: non-pt | M41: non-pt | N41: non-pt
A42: T4 | B42: L2 | C42: Zone 28 | D42: 6 | E42: 498 | F42: 0 | G42: 1 | H42: 0 | I42: 1 | J42: 0 | K42: 0 | L42: non-pt | M42: non-pt | N42: non-pt
A43: T4 | B43: L3 | C43: Zone 29 | D43: 6 | E43: 663 | F43: 1 | G43: 1 | H43: 1 | I43: 1 | J43: 1 | K43: 1 | L43: non-pt | M43: non-pt | N43: non-pt
A44: T4 | B44: L3 | C44: Zone 30 | D44: 6 | E44: 1446 | F44: 1 | G44: 1 | H44: 1 | I44: 1 | J44: 1 | K44: 1 | L44: 0.9 | M44: 0.9 | N44: pt
A45: T4 | B45: L3 | C45: Zone 31 | D45: 6 | E45: 1280 | F45: 1 | G45: 1 | H45: 1 | I45: 1 | J45: 1 | K45: 1 | L45: 0.9 | M45: 0.9 | N45: pt
A46: T4 | B46: L3 | C46: Zone 32 | D46: 6 | E46: 1925 | F46: 1 | G46: 1 | H46: 0.5 | I46: 1 | J46: 0 | K46: 0 | L46: 0.5 | M46: 0.75 | N46: pt
A47: T4 | B47: L3 | C47: Zone 33 | D47: 6 | E47: 1314 | F47: 0 | G47: 0 | H47: 0 | I47: 0 | J47: 0 | K47: 0 | L47: 0 | M47: 0 | N47: pt
A48: T4 | B48: L3 | C48: Zone 34 | D48: 6 | E48: 2034 | F48: 0 | G48: 0 | H48: 0 | I48: 0 | J48: 0 | K48: 0 | L48: 0 | M48: 0 | N48: pt
A49: T3 | B49: LG2 | C49: Zone 1 | D49: 2 | E49: 259 | F49: 1 | G49: 1 | H49: 1 | I49: 1 | J49: 1 | K49: 1 | L49: non-pt | M49: non-pt | N49: non-pt
...

Sheet pt_pivot
A1: category | B1: pt
B3: Column Labels
B4: 4 | E4: 6 | H4: Total Sum of area_m2 | I4: Total Sum of pt_pc13 | J4: Total Sum of pt_pc14
A5: Row Labels | B5: Sum of area_m2 | C5: Sum of pt_pc13 | D5: Sum of pt_pc14 | E5: Sum of area_m2 | F5: Sum of pt_pc13 | G5: Sum of pt_pc14
A6: T3 | B6: 6507 | C6: 5.35 | D6: 5.66 | H6: 6507 | I6: 5.35 | J6: 5.66
A7: L3 | B7: 2701 | C7: 3.55 | D7: 3.55 | H7: 2701 | I7: 3.55 | J7: 3.55
A8: Zone10 | B8: 729 | C8: 0.9 | D8: 0.9 | H8: 729 | I8: 0.9 | J8: 0.9
A9: Zone11 | B9: 343 | C9: 1 | D9: 1 | H9: 343 | I9: 1 | J9: 1
A10: Zone12 | B10: 838 | C10: 0.9 | D10: 0.9 | H10: 838 | I10: 0.9 | J10: 0.9
A11: Zone14 | B11: 791 | C11: 0.75 | D11: 0.75 | H11: 791 | I11: 0.75 | J11: 0.75
A12: L4 | B12: 3806 | C12: 1.8 | D12: 2.11 | H12: 3806 | I12: 1.8 | J12: 2.11
A13: Zone15 | B13: 638 | C13: 0.9 | D13: 0.9 | H13: 638 | I13: 0.9 | J13: 0.9
A14: Zone16 | B14: 1182 | C14: 0.9 | D14: 1 | H14: 1182 | I14: 0.9 | J14: 1
A15: Zone17 | B15: 858 | C15: 0 | D15: 0 | H15: 858 | I15: 0 | J15: 0
A16: Zone19 | B16: 1128 | C16: 0 | D16: 0.21 | H16: 1128 | I16: 0 | J16: 0.21
A17: T4 | E17: 17338 | F17: 8.09 | G17: 8.34 | H17: 17338 | I17: 8.09 | J17: 8.34
A18: L1M | E18: 1637 | F18: 3 | G18: 3 | H18: 1637 | I18: 3 | J18: 3
A19: Zone 16 | E19: 901 | F19: 1 | G19: 1 | H19: 901 | I19: 1 | J19: 1
A20: Zone 17 | E20: 366 | F20: 1 | G20: 1 | H20: 366 | I20: 1 | J20: 1
A21: Zone 18 | E21: 370 | F21: 1 | G21: 1 | H21: 370 | I21: 1 | J21: 1
A22: L2 | E22: 7702 | F22: 2.79 | G22: 2.79 | H22: 7702 | I22: 2.79 | J22: 2.79
A23: Zone 22 | E23: 1605 | F23: 0.9 | G23: 0.9 | H23: 1605 | I23: 0.9 | J23: 0.9
A24: Zone 23 | E24: 1265 | F24: 0.9 | G24: 0.9 | H24: 1265 | I24: 0.9 | J24: 0.9
A25: Zone 24 | E25: 1687 | F25: 0.9 | G25: 0.9 | H25: 1687 | I25: 0.9 | J25: 0.9
A26: Zone 25 | E26: 1372 | F26: 0 | G26: 0 | H26: 1372 | I26: 0 | J26: 0
A27: Zone 26 | E27: 1773 | F27: 0.09 | G27: 0.09 | H27: 1773 | I27: 0.09 | J27: 0.09
A28: L3 | E28: 7999 | F28: 2.3 | G28: 2.55 | H28: 7999 | I28: 2.3 | J28: 2.55
... A33: Zone 34 | E33: 2034 | F33: 0 | G33: 0 | H33: 2034 | I33: 0 | J33: 0
A34: Grand Total | B34: 6507 | C34: 5.35 | D34: 5.66 | E34: 17338 | F34: 8.09 | G34: 8.34 | H34: 23845 | I34: 13.44 | J34: 14

Sheet summary
A1: Tower | B1: Level | C1: SOW | D1: Zone | E1: Total_area_m2 | F1: %_progress_PC13 | G1: %_progress_PC14
A2: T3 | B2: L3 | C2: 4 | D2: =pt_pivot!A8 -> Zone10 | E2: =GETPIVOTDATA("Sum of area_m2",pt_pivot!B3,"Tower","T3","Level","L3","zone","Zone10","SOW",4) -> 729 | F2: 0.9 | G2: 0.9
A3: T3 | B3: L3 | C3: 4 | D3: =pt_pivot!A9 -> Zone11 | E3: =GETPIVOTDATA("Sum of area_m2",pt_pivot!$A$3,"Tower","T3","Level","L3","zone","Zone11","SOW",4) -> 343 | F3: 1 | G3: 1
A4: T3 | B4: L3 | C4: 4 | D4: =pt_pivot!A10 -> Zone12 | E4: =GETPIVOTDATA("Sum of area_m2",pt_pivot!$A$3,"Tower","T3","Level","L3","zone","Zone12","SOW",4) -> 838 | F4: 0.9 | G4: 0.9
A5: T3 | B5: L3 | C5: 4 | D5: =pt_pivot!A11 -> Zone14 | E5: =GETPIVOTDATA("Sum of area_m2",pt_pivot!$A$3,"Tower","T3","Level","L3","zone","Zone14","SOW",4) -> 791 | F5: 0.75 | G5: 0.75
A6: T3 | B6: L4 | C6: 4 | D6: =pt_pivot!A13 -> Zone15 | E6: =GETPIVOTDATA("Sum of area_m2",pt_pivot!$A$3,"Tower","T3","Level","L4","zone","Zone15","SOW",4) -> 638 | F6: 0.9 | G6: 0.9
A7: T3 | B7: L4 | C7: 4 | D7: =pt_pivot!A14 -> Zone16 | E7: =GETPIVOTDATA("Sum of area_m2",pt_pivot!$A$3,"Tower","T3","Level","L4","zone","Zone16","SOW",4) -> 1182 | F7: 0.9 | G7: 1
A8: T3 | B8: L4 | C8: 4 | D8: =pt_pivot!A15 -> Zone17 | E8: =GETPIVOTDATA("Sum of area_m2",pt_pivot!$A$3,"Tower","T3","Level","L4","zone","Zone17","SOW",4) -> 858 | F8: 0 | G8: 0
A9: T3 | B9: L4 | C9: 4 | D9: =pt_pivot!A16 -> Zone19 | E9: =GETPIVOTDATA("Sum of area_m2",pt_pivot!$A$3,"Tower","T3","Level","L4","zone","Zone19","SOW",4) -> 1128 | F9: 0 | G9: 0.21
A10: T4 | B10: L1M | C10: 5 | D10: =pt_pivot!A19 -> Zone 16 | E10: 901 | F10: 1 | G10: 1
A11: T4 | B11: L1M | C11: 5 | D11: =pt_pivot!A20 -> Zone 17 | E11: 366 | F11: 1 | G11: 1
A12: T4 | B12: L1M | C12: 5 | D12: =pt_pivot!A21 -> Zone 18 | E12: 370 | F12: 1 | G12: 1
A13: T4 | B13: L2 | C13: 6 | D13: =pt_pivot!A23 -> Zone 22 | E13: 1605 | F13: 0.9 | G13: 0.9
A14: T4 | B14: L2 | C14: 6 | D14: =pt_pivot!A24 -> Zone 23 | E14: 1265 | F14: 0.9 | G14: 0.9
A15: T4 | B15: L2 | C15: 6 | D15: =pt_pivot!A25 -> Zone 24 | E15: 1687 | F15: 0.9 | G15: 0.9
A16: T4 | B16: L2 | C16: 6 | D16: =pt_pivot!A26 -> Zone 25 | E16: 1372 | F16: 0 | G16: 0
A17: T4 | B17: L2 | C17: 6 | D17: =pt_pivot!A27 -> Zone 26 | E17: 1773 | F17: 0.09 | G17: 0.09
A18: T4 | B18: L3 | C18: 6 | D18: =pt_pivot!A29 -> Zone 30 | E18: 1446 | F18: 0.9 | G18: 0.9
A19: T4 | B19: L3 | C19: 6 | D19: =pt_pivot!A30 -> Zone 31 | E19: 1280 | F19: 0.9 | G19: 0.9
A20: T4 | B20: L3 | C20: 6 | D20: =pt_pivot!A31 -> Zone 32 | E20: 1925 | F20: 0.5 | G20: 0.75
A21: T4 | B21: L3 | C21: 6 | D21: =pt_pivot!A32 -> Zone 33 | E21: 1314 | F21: 0 | G21: 0
A22: T4 | B22: L3 | C22: 6 | D22: =pt_pivot!A33 -> Zone 34 | E22: 2034 | F22: 0 | G22: 0

Sheet summary_level
A1: Tower | B1: Level | C1: SOW | D1: Zone | E1: Total_area_m2 | F1: %_progress_PC13 | G1: %_progress_PC14
A2: T3 | B2: L3 | C2: 4 | D2: =pt_pivot!A8 -> Zone10 | E2: =SUM(summary!E2:E5) -> 2701 | F2: =AVERAGE(summary!F2:F5) -> 0.8875 | G2: =AVERAGE(summary!G2:G5) -> 0.8875
A3: T3 | B3: L4 | C3: 4 | D3: =pt_pivot!A13 -> Zone15 | E3: =SUM(summary!E6:E9) -> 3806 | F3: =AVERAGE(summary!F6:F9) -> 0.45 | G3: =AVERAGE(summary!G6:G9) -> 0.5275
A4: T4 | B4: L1M | C4: 5 | D4: =pt_pivot!A19 -> Zone 16 | E4: =SUM(summary!E10:E12) -> 1637 | F4: =AVERAGE(summary!F10:F12) -> 1 | G4: =AVERAGE(summary!G10:G12) -> 1
A5: T4 | B5: L2 | C5: 6 | D5: =pt_pivot!A23 -> Zone 22 | E5: =SUM(summary!E13:E17) -> 7702 | F5: =AVERAGE(summary!F13:F17) -> 0.558 | G5: =AVERAGE(summary!G13:G17) -> 0.558
A6: T4 | B6: L3 | C6: 6 | D6: =pt_pivot!A29 -> Zone 30 | E6: =SUM(summary!E18:E22) -> 7999 | F6: =AVERAGE(summary!F18:F22) -> 0.46 | G6: =AVERAGE(summary!G18:G22) -> 0.51
